Exception ignored in: <bound method BaseMySQLSocket.__del__ of <mysql.connector.network.MySQLTCPSocket object at 0x762c03b0>>
Traceback (most recent call last):
  File "/home/pi/.local/lib/python3.5/site-packages/mysql/connector/network.py", line 149, in __del__
  File "/home/pi/.local/lib/python3.5/site-packages/mysql/connector/network.py", line 137, in shutdown
AttributeError: 'NoneType' object has no attribute 'error'
